[10/03/2015 11:31:59 PM] - ERROR - status.py - MainThread - write - Traceback (most recent call last):

[10/03/2015 11:31:59 PM] - ERROR - status.py - MainThread - write -   File "/usr/bin/i3situation", line 9, in <module>

[10/03/2015 11:31:59 PM] - ERROR - status.py - MainThread - write -     
[10/03/2015 11:31:59 PM] - ERROR - status.py - MainThread - write - load_entry_point('i3situation==1.0.5', 'console_scripts', 'i3situation')()
[10/03/2015 11:31:59 PM] - ERROR - status.py - MainThread - write -   File "/usr/lib/python3.4/site-packages/i3situation/main.py", line 9, in main

[10/03/2015 11:31:59 PM] - ERROR - status.py - MainThread - write -     
[10/03/2015 11:31:59 PM] - ERROR - status.py - MainThread - write - s.run()
[10/03/2015 11:31:59 PM] - ERROR - status.py - MainThread - write -   File "/usr/lib/python3.4/site-packages/i3situation/core/status.py", line 127, in run

[10/03/2015 11:31:59 PM] - ERROR - status.py - MainThread - write -     
[10/03/2015 11:31:59 PM] - ERROR - status.py - MainThread - write - time.sleep(self.config.general['interval'])
[10/03/2015 11:31:59 PM] - ERROR - status.py - MainThread - write - KeyboardInterrupt
[10/03/2015 11:31:59 PM] - ERROR - status.py - MainThread - write - 
[10/03/2015 11:32:02 PM] - ERROR - status.py - MainThread - write - Exception ignored in: 
[10/03/2015 11:32:02 PM] - ERROR - status.py - MainThread - write - <module 'threading' from '/usr/lib/python3.4/threading.py'>
[10/03/2015 11:32:02 PM] - ERROR - status.py - MainThread - write - Traceback (most recent call last):

[10/03/2015 11:32:02 PM] - ERROR - status.py - MainThread - write -   File "/usr/lib/python3.4/threading.py", line 1294, in _shutdown

[10/03/2015 11:32:02 PM] - ERROR - status.py - MainThread - write -     
[10/03/2015 11:32:02 PM] - ERROR - status.py - MainThread - write - t.join()
[10/03/2015 11:32:02 PM] - ERROR - status.py - MainThread - write -   File "/usr/lib/python3.4/threading.py", line 1060, in join

[10/03/2015 11:32:02 PM] - ERROR - status.py - MainThread - write -     
[10/03/2015 11:32:02 PM] - ERROR - status.py - MainThread - write - self._wait_for_tstate_lock()
[10/03/2015 11:32:02 PM] - ERROR - status.py - MainThread - write -   File "/usr/lib/python3.4/threading.py", line 1076, in _wait_for_tstate_lock

[10/03/2015 11:32:02 PM] - ERROR - status.py - MainThread - write -     
[10/03/2015 11:32:02 PM] - ERROR - status.py - MainThread - write - elif lock.acquire(block, timeout):
[10/03/2015 11:32:02 PM] - ERROR - status.py - MainThread - write - KeyboardInterrupt
[10/03/2015 11:39:32 PM] - ERROR - status.py - Thread-3 - write - Exception in thread Thread-3:
Traceback (most recent call last):
  File "/usr/lib/python3.4/threading.py", line 920, in _bootstrap_inner
    self.run()
  File "/usr/lib/python3.4/site-packages/i3situation/core/plugin_manager.py", line 52, in run
    ret = self.func()
  File "usr/lib/python3.4/site-packages/i3situation/plugins/reddit.py", line 77, in main
IndexError: pop from empty list

[10/03/2015 11:39:33 PM] - ERROR - status.py - Thread-2 - write - Exception in thread Thread-2:
Traceback (most recent call last):
  File "/usr/lib/python3.4/threading.py", line 920, in _bootstrap_inner
    self.run()
  File "/usr/lib/python3.4/site-packages/i3situation/core/plugin_manager.py", line 52, in run
    ret = self.func()
  File "usr/lib/python3.4/site-packages/i3situation/plugins/reddit.py", line 77, in main
IndexError: pop from empty list

[10/03/2015 11:42:43 PM] - ERROR - status.py - MainThread - write - Traceback (most recent call last):

[10/03/2015 11:42:43 PM] - ERROR - status.py - MainThread - write -   File "/usr/bin/i3situation", line 9, in <module>

[10/03/2015 11:42:43 PM] - ERROR - status.py - MainThread - write -     
[10/03/2015 11:42:43 PM] - ERROR - status.py - MainThread - write - load_entry_point('i3situation==1.0.5', 'console_scripts', 'i3situation')()
[10/03/2015 11:42:43 PM] - ERROR - status.py - MainThread - write -   File "/usr/lib/python3.4/site-packages/i3situation/main.py", line 9, in main

[10/03/2015 11:42:43 PM] - ERROR - status.py - MainThread - write -     
[10/03/2015 11:42:43 PM] - ERROR - status.py - MainThread - write - s.run()
[10/03/2015 11:42:43 PM] - ERROR - status.py - MainThread - write -   File "/usr/lib/python3.4/site-packages/i3situation/core/status.py", line 124, in run

[10/03/2015 11:42:43 PM] - ERROR - status.py - MainThread - write -     
[10/03/2015 11:42:43 PM] - ERROR - status.py - MainThread - write - self.reload()
[10/03/2015 11:42:43 PM] - ERROR - status.py - MainThread - write -   File "/usr/lib/python3.4/site-packages/i3situation/core/status.py", line 94, in reload

[10/03/2015 11:42:43 PM] - ERROR - status.py - MainThread - write -     
[10/03/2015 11:42:43 PM] - ERROR - status.py - MainThread - write - self.config.plugin, self.config.general = self.config.reload()
[10/03/2015 11:42:43 PM] - ERROR - status.py - MainThread - write -   File "/usr/lib/python3.4/site-packages/i3situation/core/config.py", line 65, in reload

[10/03/2015 11:42:43 PM] - ERROR - status.py - MainThread - write -     
[10/03/2015 11:42:43 PM] - ERROR - status.py - MainThread - write - plugin.append(dict(self._conf.items(section)))
[10/03/2015 11:42:43 PM] - ERROR - status.py - MainThread - write -   File "/usr/lib/python3.4/configparser.py", line 836, in items

[10/03/2015 11:42:43 PM] - ERROR - status.py - MainThread - write -     
[10/03/2015 11:42:43 PM] - ERROR - status.py - MainThread - write - return [(option, value_getter(option)) for option in d.keys()]
[10/03/2015 11:42:43 PM] - ERROR - status.py - MainThread - write -   File "/usr/lib/python3.4/configparser.py", line 836, in <listcomp>

[10/03/2015 11:42:43 PM] - ERROR - status.py - MainThread - write -     
[10/03/2015 11:42:43 PM] - ERROR - status.py - MainThread - write - return [(option, value_getter(option)) for option in d.keys()]
[10/03/2015 11:42:43 PM] - ERROR - status.py - MainThread - write -   File "/usr/lib/python3.4/configparser.py", line 833, in <lambda>

[10/03/2015 11:42:43 PM] - ERROR - status.py - MainThread - write -     
[10/03/2015 11:42:43 PM] - ERROR - status.py - MainThread - write - section, option, d[option], d)
[10/03/2015 11:42:43 PM] - ERROR - status.py - MainThread - write -   File "/usr/lib/python3.4/configparser.py", line 374, in before_get

[10/03/2015 11:42:43 PM] - ERROR - status.py - MainThread - write -     
[10/03/2015 11:42:43 PM] - ERROR - status.py - MainThread - write - self._interpolate_some(parser, option, L, value, section, defaults, 1)
[10/03/2015 11:42:43 PM] - ERROR - status.py - MainThread - write -   File "/usr/lib/python3.4/configparser.py", line 423, in _interpolate_some

[10/03/2015 11:42:43 PM] - ERROR - status.py - MainThread - write -     
[10/03/2015 11:42:43 PM] - ERROR - status.py - MainThread - write - "found: %r" % (rest,))
[10/03/2015 11:42:43 PM] - ERROR - status.py - MainThread - write - configparser
[10/03/2015 11:42:43 PM] - ERROR - status.py - MainThread - write - .
[10/03/2015 11:42:43 PM] - ERROR - status.py - MainThread - write - InterpolationSyntaxError
[10/03/2015 11:42:43 PM] - ERROR - status.py - MainThread - write - : 
[10/03/2015 11:42:43 PM] - ERROR - status.py - MainThread - write - '%' must be followed by '%' or '(', found: '%'
[10/03/2015 11:43:02 PM] - ERROR - status.py - MainThread - write - Traceback (most recent call last):

[10/03/2015 11:43:02 PM] - ERROR - status.py - MainThread - write -   File "/usr/bin/i3situation", line 9, in <module>

[10/03/2015 11:43:02 PM] - ERROR - status.py - MainThread - write -     
[10/03/2015 11:43:02 PM] - ERROR - status.py - MainThread - write - load_entry_point('i3situation==1.0.5', 'console_scripts', 'i3situation')()
[10/03/2015 11:43:02 PM] - ERROR - status.py - MainThread - write -   File "/usr/lib/python3.4/site-packages/i3situation/main.py", line 7, in main

[10/03/2015 11:43:02 PM] - ERROR - status.py - MainThread - write -     
[10/03/2015 11:43:02 PM] - ERROR - status.py - MainThread - write - s = status.Status()
[10/03/2015 11:43:02 PM] - ERROR - status.py - MainThread - write -   File "/usr/lib/python3.4/site-packages/i3situation/core/status.py", line 60, in __init__

[10/03/2015 11:43:02 PM] - ERROR - status.py - MainThread - write -     
[10/03/2015 11:43:02 PM] - ERROR - status.py - MainThread - write - self._plugin_path, self.config.plugin)
[10/03/2015 11:43:02 PM] - ERROR - status.py - MainThread - write -   File "/usr/lib/python3.4/site-packages/i3situation/core/plugin_manager.py", line 123, in __init__

[10/03/2015 11:43:02 PM] - ERROR - status.py - MainThread - write -     
[10/03/2015 11:43:02 PM] - ERROR - status.py - MainThread - write - self.objects = self.load_objects()
[10/03/2015 11:43:02 PM] - ERROR - status.py - MainThread - write -   File "/usr/lib/python3.4/site-packages/i3situation/core/plugin_manager.py", line 167, in load_objects

[10/03/2015 11:43:02 PM] - ERROR - status.py - MainThread - write -     
[10/03/2015 11:43:02 PM] - ERROR - status.py - MainThread - write - if settings['plugin'] in self.plugins:
[10/03/2015 11:43:02 PM] - ERROR - status.py - MainThread - write - KeyError
[10/03/2015 11:43:02 PM] - ERROR - status.py - MainThread - write - : 
[10/03/2015 11:43:02 PM] - ERROR - status.py - MainThread - write - 'plugin'
[10/03/2015 11:43:45 PM] - ERROR - status.py - MainThread - write - Traceback (most recent call last):

[10/03/2015 11:43:45 PM] - ERROR - status.py - MainThread - write -   File "/usr/bin/i3situation", line 9, in <module>

[10/03/2015 11:43:45 PM] - ERROR - status.py - MainThread - write -     
[10/03/2015 11:43:45 PM] - ERROR - status.py - MainThread - write - load_entry_point('i3situation==1.0.5', 'console_scripts', 'i3situation')()
[10/03/2015 11:43:45 PM] - ERROR - status.py - MainThread - write -   File "/usr/lib/python3.4/site-packages/i3situation/main.py", line 7, in main

[10/03/2015 11:43:45 PM] - ERROR - status.py - MainThread - write -     
[10/03/2015 11:43:45 PM] - ERROR - status.py - MainThread - write - s = status.Status()
[10/03/2015 11:43:45 PM] - ERROR - status.py - MainThread - write -   File "/usr/lib/python3.4/site-packages/i3situation/core/status.py", line 60, in __init__

[10/03/2015 11:43:45 PM] - ERROR - status.py - MainThread - write -     
[10/03/2015 11:43:45 PM] - ERROR - status.py - MainThread - write - self._plugin_path, self.config.plugin)
[10/03/2015 11:43:45 PM] - ERROR - status.py - MainThread - write -   File "/usr/lib/python3.4/site-packages/i3situation/core/plugin_manager.py", line 123, in __init__

[10/03/2015 11:43:45 PM] - ERROR - status.py - MainThread - write -     
[10/03/2015 11:43:45 PM] - ERROR - status.py - MainThread - write - self.objects = self.load_objects()
[10/03/2015 11:43:45 PM] - ERROR - status.py - MainThread - write -   File "/usr/lib/python3.4/site-packages/i3situation/core/plugin_manager.py", line 167, in load_objects

[10/03/2015 11:43:45 PM] - ERROR - status.py - MainThread - write -     
[10/03/2015 11:43:45 PM] - ERROR - status.py - MainThread - write - if settings['plugin'] in self.plugins:
[10/03/2015 11:43:45 PM] - ERROR - status.py - MainThread - write - KeyError
[10/03/2015 11:43:45 PM] - ERROR - status.py - MainThread - write - : 
[10/03/2015 11:43:45 PM] - ERROR - status.py - MainThread - write - 'plugin'
[10/03/2015 11:43:55 PM] - ERROR - status.py - MainThread - write - Traceback (most recent call last):

[10/03/2015 11:43:55 PM] - ERROR - status.py - MainThread - write -   File "/usr/bin/i3situation", line 9, in <module>

[10/03/2015 11:43:55 PM] - ERROR - status.py - MainThread - write -     
[10/03/2015 11:43:55 PM] - ERROR - status.py - MainThread - write - load_entry_point('i3situation==1.0.5', 'console_scripts', 'i3situation')()
[10/03/2015 11:43:55 PM] - ERROR - status.py - MainThread - write -   File "/usr/lib/python3.4/site-packages/i3situation/main.py", line 7, in main

[10/03/2015 11:43:55 PM] - ERROR - status.py - MainThread - write -     
[10/03/2015 11:43:55 PM] - ERROR - status.py - MainThread - write - s = status.Status()
[10/03/2015 11:43:55 PM] - ERROR - status.py - MainThread - write -   File "/usr/lib/python3.4/site-packages/i3situation/core/status.py", line 60, in __init__

[10/03/2015 11:43:55 PM] - ERROR - status.py - MainThread - write -     
[10/03/2015 11:43:55 PM] - ERROR - status.py - MainThread - write - self._plugin_path, self.config.plugin)
[10/03/2015 11:43:55 PM] - ERROR - status.py - MainThread - write -   File "/usr/lib/python3.4/site-packages/i3situation/core/plugin_manager.py", line 123, in __init__

[10/03/2015 11:43:55 PM] - ERROR - status.py - MainThread - write -     
[10/03/2015 11:43:55 PM] - ERROR - status.py - MainThread - write - self.objects = self.load_objects()
[10/03/2015 11:43:55 PM] - ERROR - status.py - MainThread - write -   File "/usr/lib/python3.4/site-packages/i3situation/core/plugin_manager.py", line 167, in load_objects

[10/03/2015 11:43:55 PM] - ERROR - status.py - MainThread - write -     
[10/03/2015 11:43:55 PM] - ERROR - status.py - MainThread - write - if settings['plugin'] in self.plugins:
[10/03/2015 11:43:55 PM] - ERROR - status.py - MainThread - write - KeyError
[10/03/2015 11:43:55 PM] - ERROR - status.py - MainThread - write - : 
[10/03/2015 11:43:55 PM] - ERROR - status.py - MainThread - write - 'plugin'
[10/03/2015 11:47:59 PM] - ERROR - status.py - MainThread - write - Traceback (most recent call last):

[10/03/2015 11:47:59 PM] - ERROR - status.py - MainThread - write -   File "/usr/bin/i3situation", line 9, in <module>

[10/03/2015 11:47:59 PM] - ERROR - status.py - MainThread - write -     
[10/03/2015 11:47:59 PM] - ERROR - status.py - MainThread - write - load_entry_point('i3situation==1.0.5', 'console_scripts', 'i3situation')()
[10/03/2015 11:47:59 PM] - ERROR - status.py - MainThread - write -   File "/usr/lib/python3.4/site-packages/i3situation/main.py", line 7, in main

[10/03/2015 11:47:59 PM] - ERROR - status.py - MainThread - write -     
[10/03/2015 11:47:59 PM] - ERROR - status.py - MainThread - write - s = status.Status()
[10/03/2015 11:47:59 PM] - ERROR - status.py - MainThread - write -   File "/usr/lib/python3.4/site-packages/i3situation/core/status.py", line 60, in __init__

[10/03/2015 11:47:59 PM] - ERROR - status.py - MainThread - write -     
[10/03/2015 11:47:59 PM] - ERROR - status.py - MainThread - write - self._plugin_path, self.config.plugin)
[10/03/2015 11:47:59 PM] - ERROR - status.py - MainThread - write -   File "/usr/lib/python3.4/site-packages/i3situation/core/plugin_manager.py", line 123, in __init__

[10/03/2015 11:47:59 PM] - ERROR - status.py - MainThread - write -     
[10/03/2015 11:47:59 PM] - ERROR - status.py - MainThread - write - self.objects = self.load_objects()
[10/03/2015 11:47:59 PM] - ERROR - status.py - MainThread - write -   File "/usr/lib/python3.4/site-packages/i3situation/core/plugin_manager.py", line 167, in load_objects

[10/03/2015 11:47:59 PM] - ERROR - status.py - MainThread - write -     
[10/03/2015 11:47:59 PM] - ERROR - status.py - MainThread - write - if settings['plugin'] in self.plugins:
[10/03/2015 11:47:59 PM] - ERROR - status.py - MainThread - write - KeyError
[10/03/2015 11:47:59 PM] - ERROR - status.py - MainThread - write - : 
[10/03/2015 11:47:59 PM] - ERROR - status.py - MainThread - write - 'plugin'
[10/03/2015 11:48:04 PM] - ERROR - status.py - MainThread - write - Traceback (most recent call last):

[10/03/2015 11:48:04 PM] - ERROR - status.py - MainThread - write -   File "/usr/bin/i3situation", line 9, in <module>

[10/03/2015 11:48:04 PM] - ERROR - status.py - MainThread - write -     
[10/03/2015 11:48:04 PM] - ERROR - status.py - MainThread - write - load_entry_point('i3situation==1.0.5', 'console_scripts', 'i3situation')()
[10/03/2015 11:48:04 PM] - ERROR - status.py - MainThread - write -   File "/usr/lib/python3.4/site-packages/i3situation/main.py", line 7, in main

[10/03/2015 11:48:04 PM] - ERROR - status.py - MainThread - write -     
[10/03/2015 11:48:04 PM] - ERROR - status.py - MainThread - write - s = status.Status()
[10/03/2015 11:48:04 PM] - ERROR - status.py - MainThread - write -   File "/usr/lib/python3.4/site-packages/i3situation/core/status.py", line 60, in __init__

[10/03/2015 11:48:04 PM] - ERROR - status.py - MainThread - write -     
[10/03/2015 11:48:04 PM] - ERROR - status.py - MainThread - write - self._plugin_path, self.config.plugin)
[10/03/2015 11:48:04 PM] - ERROR - status.py - MainThread - write -   File "/usr/lib/python3.4/site-packages/i3situation/core/plugin_manager.py", line 123, in __init__

[10/03/2015 11:48:04 PM] - ERROR - status.py - MainThread - write -     
[10/03/2015 11:48:04 PM] - ERROR - status.py - MainThread - write - self.objects = self.load_objects()
[10/03/2015 11:48:04 PM] - ERROR - status.py - MainThread - write -   File "/usr/lib/python3.4/site-packages/i3situation/core/plugin_manager.py", line 167, in load_objects

[10/03/2015 11:48:04 PM] - ERROR - status.py - MainThread - write -     
[10/03/2015 11:48:04 PM] - ERROR - status.py - MainThread - write - if settings['plugin'] in self.plugins:
[10/03/2015 11:48:04 PM] - ERROR - status.py - MainThread - write - KeyError
[10/03/2015 11:48:04 PM] - ERROR - status.py - MainThread - write - : 
[10/03/2015 11:48:04 PM] - ERROR - status.py - MainThread - write - 'plugin'
[10/03/2015 11:48:29 PM] - ERROR - status.py - MainThread - write - Traceback (most recent call last):

[10/03/2015 11:48:29 PM] - ERROR - status.py - MainThread - write -   File "/usr/bin/i3situation", line 9, in <module>

[10/03/2015 11:48:29 PM] - ERROR - status.py - MainThread - write -     
[10/03/2015 11:48:29 PM] - ERROR - status.py - MainThread - write - load_entry_point('i3situation==1.0.5', 'console_scripts', 'i3situation')()
[10/03/2015 11:48:29 PM] - ERROR - status.py - MainThread - write -   File "/usr/lib/python3.4/site-packages/i3situation/main.py", line 9, in main

[10/03/2015 11:48:29 PM] - ERROR - status.py - MainThread - write -     
[10/03/2015 11:48:29 PM] - ERROR - status.py - MainThread - write - s.run()
[10/03/2015 11:48:29 PM] - ERROR - status.py - MainThread - write -   File "/usr/lib/python3.4/site-packages/i3situation/core/status.py", line 124, in run

[10/03/2015 11:48:29 PM] - ERROR - status.py - MainThread - write -     
[10/03/2015 11:48:29 PM] - ERROR - status.py - MainThread - write - self.reload()
[10/03/2015 11:48:29 PM] - ERROR - status.py - MainThread - write -   File "/usr/lib/python3.4/site-packages/i3situation/core/status.py", line 97, in reload

[10/03/2015 11:48:29 PM] - ERROR - status.py - MainThread - write -     
[10/03/2015 11:48:29 PM] - ERROR - status.py - MainThread - write - self._plugin_path, self.config.plugin)
[10/03/2015 11:48:29 PM] - ERROR - status.py - MainThread - write -   File "/usr/lib/python3.4/site-packages/i3situation/core/plugin_manager.py", line 123, in __init__

[10/03/2015 11:48:29 PM] - ERROR - status.py - MainThread - write -     
[10/03/2015 11:48:29 PM] - ERROR - status.py - MainThread - write - self.objects = self.load_objects()
[10/03/2015 11:48:29 PM] - ERROR - status.py - MainThread - write -   File "/usr/lib/python3.4/site-packages/i3situation/core/plugin_manager.py", line 167, in load_objects

[10/03/2015 11:48:29 PM] - ERROR - status.py - MainThread - write -     
[10/03/2015 11:48:29 PM] - ERROR - status.py - MainThread - write - if settings['plugin'] in self.plugins:
[10/03/2015 11:48:29 PM] - ERROR - status.py - MainThread - write - KeyError
[10/03/2015 11:48:29 PM] - ERROR - status.py - MainThread - write - : 
[10/03/2015 11:48:29 PM] - ERROR - status.py - MainThread - write - 'plugin'
[10/03/2015 11:48:31 PM] - ERROR - status.py - MainThread - write - Traceback (most recent call last):

[10/03/2015 11:48:31 PM] - ERROR - status.py - MainThread - write -   File "/usr/bin/i3situation", line 9, in <module>

[10/03/2015 11:48:31 PM] - ERROR - status.py - MainThread - write -     
[10/03/2015 11:48:31 PM] - ERROR - status.py - MainThread - write - load_entry_point('i3situation==1.0.5', 'console_scripts', 'i3situation')()
[10/03/2015 11:48:31 PM] - ERROR - status.py - MainThread - write -   File "/usr/lib/python3.4/site-packages/i3situation/main.py", line 7, in main

[10/03/2015 11:48:31 PM] - ERROR - status.py - MainThread - write -     
[10/03/2015 11:48:31 PM] - ERROR - status.py - MainThread - write - s = status.Status()
[10/03/2015 11:48:31 PM] - ERROR - status.py - MainThread - write -   File "/usr/lib/python3.4/site-packages/i3situation/core/status.py", line 60, in __init__

[10/03/2015 11:48:31 PM] - ERROR - status.py - MainThread - write -     
[10/03/2015 11:48:31 PM] - ERROR - status.py - MainThread - write - self._plugin_path, self.config.plugin)
[10/03/2015 11:48:31 PM] - ERROR - status.py - MainThread - write -   File "/usr/lib/python3.4/site-packages/i3situation/core/plugin_manager.py", line 123, in __init__

[10/03/2015 11:48:31 PM] - ERROR - status.py - MainThread - write -     
[10/03/2015 11:48:31 PM] - ERROR - status.py - MainThread - write - self.objects = self.load_objects()
[10/03/2015 11:48:31 PM] - ERROR - status.py - MainThread - write -   File "/usr/lib/python3.4/site-packages/i3situation/core/plugin_manager.py", line 167, in load_objects

[10/03/2015 11:48:31 PM] - ERROR - status.py - MainThread - write -     
[10/03/2015 11:48:31 PM] - ERROR - status.py - MainThread - write - if settings['plugin'] in self.plugins:
[10/03/2015 11:48:31 PM] - ERROR - status.py - MainThread - write - KeyError
[10/03/2015 11:48:31 PM] - ERROR - status.py - MainThread - write - : 
[10/03/2015 11:48:31 PM] - ERROR - status.py - MainThread - write - 'plugin'
[10/03/2015 11:48:41 PM] - ERROR - status.py - MainThread - write - Traceback (most recent call last):

[10/03/2015 11:48:41 PM] - ERROR - status.py - MainThread - write -   File "/usr/bin/i3situation", line 9, in <module>

[10/03/2015 11:48:41 PM] - ERROR - status.py - MainThread - write -     
[10/03/2015 11:48:41 PM] - ERROR - status.py - MainThread - write - load_entry_point('i3situation==1.0.5', 'console_scripts', 'i3situation')()
[10/03/2015 11:48:41 PM] - ERROR - status.py - MainThread - write -   File "/usr/lib/python3.4/site-packages/i3situation/main.py", line 7, in main

[10/03/2015 11:48:41 PM] - ERROR - status.py - MainThread - write -     
[10/03/2015 11:48:41 PM] - ERROR - status.py - MainThread - write - s = status.Status()
[10/03/2015 11:48:41 PM] - ERROR - status.py - MainThread - write -   File "/usr/lib/python3.4/site-packages/i3situation/core/status.py", line 60, in __init__

[10/03/2015 11:48:41 PM] - ERROR - status.py - MainThread - write -     
[10/03/2015 11:48:41 PM] - ERROR - status.py - MainThread - write - self._plugin_path, self.config.plugin)
[10/03/2015 11:48:41 PM] - ERROR - status.py - MainThread - write -   File "/usr/lib/python3.4/site-packages/i3situation/core/plugin_manager.py", line 123, in __init__

[10/03/2015 11:48:41 PM] - ERROR - status.py - MainThread - write -     
[10/03/2015 11:48:41 PM] - ERROR - status.py - MainThread - write - self.objects = self.load_objects()
[10/03/2015 11:48:41 PM] - ERROR - status.py - MainThread - write -   File "/usr/lib/python3.4/site-packages/i3situation/core/plugin_manager.py", line 167, in load_objects

[10/03/2015 11:48:41 PM] - ERROR - status.py - MainThread - write -     
[10/03/2015 11:48:41 PM] - ERROR - status.py - MainThread - write - if settings['plugin'] in self.plugins:
[10/03/2015 11:48:41 PM] - ERROR - status.py - MainThread - write - KeyError
[10/03/2015 11:48:41 PM] - ERROR - status.py - MainThread - write - : 
[10/03/2015 11:48:41 PM] - ERROR - status.py - MainThread - write - 'plugin'
[10/03/2015 11:48:48 PM] - ERROR - status.py - MainThread - write - Traceback (most recent call last):

[10/03/2015 11:48:48 PM] - ERROR - status.py - MainThread - write -   File "/usr/bin/i3situation", line 9, in <module>

[10/03/2015 11:48:48 PM] - ERROR - status.py - MainThread - write -     
[10/03/2015 11:48:48 PM] - ERROR - status.py - MainThread - write - load_entry_point('i3situation==1.0.5', 'console_scripts', 'i3situation')()
[10/03/2015 11:48:48 PM] - ERROR - status.py - MainThread - write -   File "/usr/lib/python3.4/site-packages/i3situation/main.py", line 7, in main

[10/03/2015 11:48:48 PM] - ERROR - status.py - MainThread - write -     
[10/03/2015 11:48:48 PM] - ERROR - status.py - MainThread - write - s = status.Status()
[10/03/2015 11:48:48 PM] - ERROR - status.py - MainThread - write -   File "/usr/lib/python3.4/site-packages/i3situation/core/status.py", line 60, in __init__

[10/03/2015 11:48:48 PM] - ERROR - status.py - MainThread - write -     
[10/03/2015 11:48:48 PM] - ERROR - status.py - MainThread - write - self._plugin_path, self.config.plugin)
[10/03/2015 11:48:48 PM] - ERROR - status.py - MainThread - write -   File "/usr/lib/python3.4/site-packages/i3situation/core/plugin_manager.py", line 123, in __init__

[10/03/2015 11:48:48 PM] - ERROR - status.py - MainThread - write -     
[10/03/2015 11:48:48 PM] - ERROR - status.py - MainThread - write - self.objects = self.load_objects()
[10/03/2015 11:48:48 PM] - ERROR - status.py - MainThread - write -   File "/usr/lib/python3.4/site-packages/i3situation/core/plugin_manager.py", line 167, in load_objects

[10/03/2015 11:48:48 PM] - ERROR - status.py - MainThread - write -     
[10/03/2015 11:48:48 PM] - ERROR - status.py - MainThread - write - if settings['plugin'] in self.plugins:
[10/03/2015 11:48:48 PM] - ERROR - status.py - MainThread - write - KeyError
[10/03/2015 11:48:48 PM] - ERROR - status.py - MainThread - write - : 
[10/03/2015 11:48:48 PM] - ERROR - status.py - MainThread - write - 'plugin'
[10/03/2015 11:52:33 PM] - ERROR - status.py - MainThread - write - Traceback (most recent call last):

[10/03/2015 11:52:33 PM] - ERROR - status.py - MainThread - write -   File "/usr/bin/i3situation", line 9, in <module>

[10/03/2015 11:52:33 PM] - ERROR - status.py - MainThread - write -     
[10/03/2015 11:52:33 PM] - ERROR - status.py - MainThread - write - load_entry_point('i3situation==1.0.5', 'console_scripts', 'i3situation')()
[10/03/2015 11:52:33 PM] - ERROR - status.py - MainThread - write -   File "/usr/lib/python3.4/site-packages/i3situation/main.py", line 9, in main

[10/03/2015 11:52:33 PM] - ERROR - status.py - MainThread - write -     
[10/03/2015 11:52:33 PM] - ERROR - status.py - MainThread - write - s.run()
[10/03/2015 11:52:33 PM] - ERROR - status.py - MainThread - write -   File "/usr/lib/python3.4/site-packages/i3situation/core/status.py", line 124, in run

[10/03/2015 11:52:33 PM] - ERROR - status.py - MainThread - write -     
[10/03/2015 11:52:33 PM] - ERROR - status.py - MainThread - write - self.reload()
[10/03/2015 11:52:33 PM] - ERROR - status.py - MainThread - write -   File "/usr/lib/python3.4/site-packages/i3situation/core/status.py", line 97, in reload

[10/03/2015 11:52:33 PM] - ERROR - status.py - MainThread - write -     
[10/03/2015 11:52:33 PM] - ERROR - status.py - MainThread - write - self._plugin_path, self.config.plugin)
[10/03/2015 11:52:33 PM] - ERROR - status.py - MainThread - write -   File "/usr/lib/python3.4/site-packages/i3situation/core/plugin_manager.py", line 123, in __init__

[10/03/2015 11:52:33 PM] - ERROR - status.py - MainThread - write -     
[10/03/2015 11:52:33 PM] - ERROR - status.py - MainThread - write - self.objects = self.load_objects()
[10/03/2015 11:52:33 PM] - ERROR - status.py - MainThread - write -   File "/usr/lib/python3.4/site-packages/i3situation/core/plugin_manager.py", line 167, in load_objects

[10/03/2015 11:52:33 PM] - ERROR - status.py - MainThread - write -     
[10/03/2015 11:52:33 PM] - ERROR - status.py - MainThread - write - if settings['plugin'] in self.plugins:
[10/03/2015 11:52:33 PM] - ERROR - status.py - MainThread - write - KeyError
[10/03/2015 11:52:33 PM] - ERROR - status.py - MainThread - write - : 
[10/03/2015 11:52:33 PM] - ERROR - status.py - MainThread - write - 'plugin'
[10/03/2015 11:52:34 PM] - ERROR - status.py - MainThread - write - Traceback (most recent call last):

[10/03/2015 11:52:34 PM] - ERROR - status.py - MainThread - write -   File "/usr/bin/i3situation", line 9, in <module>

[10/03/2015 11:52:34 PM] - ERROR - status.py - MainThread - write -     
[10/03/2015 11:52:34 PM] - ERROR - status.py - MainThread - write - load_entry_point('i3situation==1.0.5', 'console_scripts', 'i3situation')()
[10/03/2015 11:52:34 PM] - ERROR - status.py - MainThread - write -   File "/usr/lib/python3.4/site-packages/i3situation/main.py", line 7, in main

[10/03/2015 11:52:34 PM] - ERROR - status.py - MainThread - write -     
[10/03/2015 11:52:34 PM] - ERROR - status.py - MainThread - write - s = status.Status()
[10/03/2015 11:52:34 PM] - ERROR - status.py - MainThread - write -   File "/usr/lib/python3.4/site-packages/i3situation/core/status.py", line 60, in __init__

[10/03/2015 11:52:34 PM] - ERROR - status.py - MainThread - write -     
[10/03/2015 11:52:34 PM] - ERROR - status.py - MainThread - write - self._plugin_path, self.config.plugin)
[10/03/2015 11:52:34 PM] - ERROR - status.py - MainThread - write -   File "/usr/lib/python3.4/site-packages/i3situation/core/plugin_manager.py", line 123, in __init__

[10/03/2015 11:52:34 PM] - ERROR - status.py - MainThread - write -     
[10/03/2015 11:52:34 PM] - ERROR - status.py - MainThread - write - self.objects = self.load_objects()
[10/03/2015 11:52:34 PM] - ERROR - status.py - MainThread - write -   File "/usr/lib/python3.4/site-packages/i3situation/core/plugin_manager.py", line 167, in load_objects

[10/03/2015 11:52:34 PM] - ERROR - status.py - MainThread - write -     
[10/03/2015 11:52:34 PM] - ERROR - status.py - MainThread - write - if settings['plugin'] in self.plugins:
[10/03/2015 11:52:34 PM] - ERROR - status.py - MainThread - write - KeyError
[10/03/2015 11:52:34 PM] - ERROR - status.py - MainThread - write - : 
[10/03/2015 11:52:34 PM] - ERROR - status.py - MainThread - write - 'plugin'
[10/03/2015 11:53:14 PM] - ERROR - status.py - MainThread - write - Traceback (most recent call last):

[10/03/2015 11:53:14 PM] - ERROR - status.py - MainThread - write -   File "/usr/bin/i3situation", line 9, in <module>

[10/03/2015 11:53:14 PM] - ERROR - status.py - MainThread - write -     
[10/03/2015 11:53:14 PM] - ERROR - status.py - MainThread - write - load_entry_point('i3situation==1.0.5', 'console_scripts', 'i3situation')()
[10/03/2015 11:53:14 PM] - ERROR - status.py - MainThread - write -   File "/usr/lib/python3.4/site-packages/i3situation/main.py", line 9, in main

[10/03/2015 11:53:14 PM] - ERROR - status.py - MainThread - write -     
[10/03/2015 11:53:14 PM] - ERROR - status.py - MainThread - write - s.run()
[10/03/2015 11:53:14 PM] - ERROR - status.py - MainThread - write -   File "/usr/lib/python3.4/site-packages/i3situation/core/status.py", line 124, in run

[10/03/2015 11:53:14 PM] - ERROR - status.py - MainThread - write -     
[10/03/2015 11:53:14 PM] - ERROR - status.py - MainThread - write - self.reload()
[10/03/2015 11:53:14 PM] - ERROR - status.py - MainThread - write -   File "/usr/lib/python3.4/site-packages/i3situation/core/status.py", line 94, in reload

[10/03/2015 11:53:14 PM] - ERROR - status.py - MainThread - write -     
[10/03/2015 11:53:14 PM] - ERROR - status.py - MainThread - write - self.config.plugin, self.config.general = self.config.reload()
[10/03/2015 11:53:14 PM] - ERROR - status.py - MainThread - write -   File "/usr/lib/python3.4/site-packages/i3situation/core/config.py", line 65, in reload

[10/03/2015 11:53:14 PM] - ERROR - status.py - MainThread - write -     
[10/03/2015 11:53:14 PM] - ERROR - status.py - MainThread - write - plugin.append(dict(self._conf.items(section)))
[10/03/2015 11:53:14 PM] - ERROR - status.py - MainThread - write -   File "/usr/lib/python3.4/configparser.py", line 836, in items

[10/03/2015 11:53:14 PM] - ERROR - status.py - MainThread - write -     
[10/03/2015 11:53:14 PM] - ERROR - status.py - MainThread - write - return [(option, value_getter(option)) for option in d.keys()]
[10/03/2015 11:53:14 PM] - ERROR - status.py - MainThread - write -   File "/usr/lib/python3.4/configparser.py", line 836, in <listcomp>

[10/03/2015 11:53:14 PM] - ERROR - status.py - MainThread - write -     
[10/03/2015 11:53:14 PM] - ERROR - status.py - MainThread - write - return [(option, value_getter(option)) for option in d.keys()]
[10/03/2015 11:53:14 PM] - ERROR - status.py - MainThread - write -   File "/usr/lib/python3.4/configparser.py", line 833, in <lambda>

[10/03/2015 11:53:14 PM] - ERROR - status.py - MainThread - write -     
[10/03/2015 11:53:14 PM] - ERROR - status.py - MainThread - write - section, option, d[option], d)
[10/03/2015 11:53:14 PM] - ERROR - status.py - MainThread - write -   File "/usr/lib/python3.4/configparser.py", line 374, in before_get

[10/03/2015 11:53:14 PM] - ERROR - status.py - MainThread - write -     
[10/03/2015 11:53:14 PM] - ERROR - status.py - MainThread - write - self._interpolate_some(parser, option, L, value, section, defaults, 1)
[10/03/2015 11:53:14 PM] - ERROR - status.py - MainThread - write -   File "/usr/lib/python3.4/configparser.py", line 423, in _interpolate_some

[10/03/2015 11:53:14 PM] - ERROR - status.py - MainThread - write -     
[10/03/2015 11:53:14 PM] - ERROR - status.py - MainThread - write - "found: %r" % (rest,))
[10/03/2015 11:53:14 PM] - ERROR - status.py - MainThread - write - configparser
[10/03/2015 11:53:14 PM] - ERROR - status.py - MainThread - write - .
[10/03/2015 11:53:14 PM] - ERROR - status.py - MainThread - write - InterpolationSyntaxError
[10/03/2015 11:53:14 PM] - ERROR - status.py - MainThread - write - : 
[10/03/2015 11:53:14 PM] - ERROR - status.py - MainThread - write - '%' must be followed by '%' or '(', found: '%'
[10/03/2015 11:58:56 PM] - ERROR - status.py - MainThread - write - Traceback (most recent call last):

[10/03/2015 11:58:56 PM] - ERROR - status.py - MainThread - write -   File "/usr/bin/i3situation", line 9, in <module>

[10/03/2015 11:58:56 PM] - ERROR - status.py - MainThread - write -     
[10/03/2015 11:58:56 PM] - ERROR - status.py - MainThread - write - load_entry_point('i3situation==1.0.5', 'console_scripts', 'i3situation')()
[10/03/2015 11:58:56 PM] - ERROR - status.py - MainThread - write -   File "/usr/lib/python3.4/site-packages/i3situation/main.py", line 9, in main

[10/03/2015 11:58:56 PM] - ERROR - status.py - MainThread - write -     
[10/03/2015 11:58:56 PM] - ERROR - status.py - MainThread - write - s.run()
[10/03/2015 11:58:56 PM] - ERROR - status.py - MainThread - write -   File "/usr/lib/python3.4/site-packages/i3situation/core/status.py", line 124, in run

[10/03/2015 11:58:56 PM] - ERROR - status.py - MainThread - write -     
[10/03/2015 11:58:56 PM] - ERROR - status.py - MainThread - write - self.reload()
[10/03/2015 11:58:56 PM] - ERROR - status.py - MainThread - write -   File "/usr/lib/python3.4/site-packages/i3situation/core/status.py", line 97, in reload

[10/03/2015 11:58:56 PM] - ERROR - status.py - MainThread - write -     
[10/03/2015 11:58:56 PM] - ERROR - status.py - MainThread - write - self._plugin_path, self.config.plugin)
[10/03/2015 11:58:56 PM] - ERROR - status.py - MainThread - write -   File "/usr/lib/python3.4/site-packages/i3situation/core/plugin_manager.py", line 123, in __init__

[10/03/2015 11:58:56 PM] - ERROR - status.py - MainThread - write -     
[10/03/2015 11:58:56 PM] - ERROR - status.py - MainThread - write - self.objects = self.load_objects()
[10/03/2015 11:58:56 PM] - ERROR - status.py - MainThread - write -   File "/usr/lib/python3.4/site-packages/i3situation/core/plugin_manager.py", line 167, in load_objects

[10/03/2015 11:58:56 PM] - ERROR - status.py - MainThread - write -     
[10/03/2015 11:58:56 PM] - ERROR - status.py - MainThread - write - if settings['plugin'] in self.plugins:
[10/03/2015 11:58:56 PM] - ERROR - status.py - MainThread - write - KeyError
[10/03/2015 11:58:56 PM] - ERROR - status.py - MainThread - write - : 
[10/03/2015 11:58:56 PM] - ERROR - status.py - MainThread - write - 'plugin'
[10/03/2015 11:59:03 PM] - ERROR - status.py - MainThread - write - Traceback (most recent call last):

[10/03/2015 11:59:03 PM] - ERROR - status.py - MainThread - write -   File "/usr/bin/i3situation", line 9, in <module>

[10/03/2015 11:59:03 PM] - ERROR - status.py - MainThread - write -     
[10/03/2015 11:59:03 PM] - ERROR - status.py - MainThread - write - load_entry_point('i3situation==1.0.5', 'console_scripts', 'i3situation')()
[10/03/2015 11:59:03 PM] - ERROR - status.py - MainThread - write -   File "/usr/lib/python3.4/site-packages/i3situation/main.py", line 7, in main

[10/03/2015 11:59:03 PM] - ERROR - status.py - MainThread - write -     
[10/03/2015 11:59:03 PM] - ERROR - status.py - MainThread - write - s = status.Status()
[10/03/2015 11:59:03 PM] - ERROR - status.py - MainThread - write -   File "/usr/lib/python3.4/site-packages/i3situation/core/status.py", line 60, in __init__

[10/03/2015 11:59:03 PM] - ERROR - status.py - MainThread - write -     
[10/03/2015 11:59:03 PM] - ERROR - status.py - MainThread - write - self._plugin_path, self.config.plugin)
[10/03/2015 11:59:03 PM] - ERROR - status.py - MainThread - write -   File "/usr/lib/python3.4/site-packages/i3situation/core/plugin_manager.py", line 123, in __init__

[10/03/2015 11:59:03 PM] - ERROR - status.py - MainThread - write -     
[10/03/2015 11:59:03 PM] - ERROR - status.py - MainThread - write - self.objects = self.load_objects()
[10/03/2015 11:59:03 PM] - ERROR - status.py - MainThread - write -   File "/usr/lib/python3.4/site-packages/i3situation/core/plugin_manager.py", line 167, in load_objects

[10/03/2015 11:59:03 PM] - ERROR - status.py - MainThread - write -     
[10/03/2015 11:59:03 PM] - ERROR - status.py - MainThread - write - if settings['plugin'] in self.plugins:
[10/03/2015 11:59:03 PM] - ERROR - status.py - MainThread - write - KeyError
[10/03/2015 11:59:03 PM] - ERROR - status.py - MainThread - write - : 
[10/03/2015 11:59:03 PM] - ERROR - status.py - MainThread - write - 'plugin'
[11/03/2015 12:03:29 AM] - CRITICAL - plugin_manager.py - MainThread - load_objects - Missing plugin date was not found in /home/i4k/.config/i3situation/plugins
[11/03/2015 12:03:29 AM] - ERROR - status.py - MainThread - write - Traceback (most recent call last):

[11/03/2015 12:03:29 AM] - ERROR - status.py - MainThread - write -   File "/usr/bin/i3situation", line 9, in <module>

[11/03/2015 12:03:29 AM] - ERROR - status.py - MainThread - write -     
[11/03/2015 12:03:29 AM] - ERROR - status.py - MainThread - write - load_entry_point('i3situation==1.0.5', 'console_scripts', 'i3situation')()
[11/03/2015 12:03:29 AM] - ERROR - status.py - MainThread - write -   File "/usr/lib/python3.4/site-packages/i3situation/main.py", line 9, in main

[11/03/2015 12:03:29 AM] - ERROR - status.py - MainThread - write -     
[11/03/2015 12:03:29 AM] - ERROR - status.py - MainThread - write - s.run()
[11/03/2015 12:03:29 AM] - ERROR - status.py - MainThread - write -   File "/usr/lib/python3.4/site-packages/i3situation/core/status.py", line 124, in run

[11/03/2015 12:03:29 AM] - ERROR - status.py - MainThread - write -     
[11/03/2015 12:03:29 AM] - ERROR - status.py - MainThread - write - self.reload()
[11/03/2015 12:03:29 AM] - ERROR - status.py - MainThread - write -   File "/usr/lib/python3.4/site-packages/i3situation/core/status.py", line 97, in reload

[11/03/2015 12:03:29 AM] - ERROR - status.py - MainThread - write -     
[11/03/2015 12:03:29 AM] - ERROR - status.py - MainThread - write - self._plugin_path, self.config.plugin)
[11/03/2015 12:03:29 AM] - ERROR - status.py - MainThread - write -   File "/usr/lib/python3.4/site-packages/i3situation/core/plugin_manager.py", line 123, in __init__

[11/03/2015 12:03:29 AM] - ERROR - status.py - MainThread - write -     
[11/03/2015 12:03:29 AM] - ERROR - status.py - MainThread - write - self.objects = self.load_objects()
[11/03/2015 12:03:29 AM] - ERROR - status.py - MainThread - write -   File "/usr/lib/python3.4/site-packages/i3situation/core/plugin_manager.py", line 179, in load_objects

[11/03/2015 12:03:29 AM] - ERROR - status.py - MainThread - write -     
[11/03/2015 12:03:29 AM] - ERROR - status.py - MainThread - write - settings['plugin'], self.dir_path))
[11/03/2015 12:03:29 AM] - ERROR - status.py - MainThread - write - i3situation.core.plugin_manager
[11/03/2015 12:03:29 AM] - ERROR - status.py - MainThread - write - .
[11/03/2015 12:03:29 AM] - ERROR - status.py - MainThread - write - MissingPlugin
[11/03/2015 12:03:29 AM] - ERROR - status.py - MainThread - write - : 
[11/03/2015 12:03:29 AM] - ERROR - status.py - MainThread - write - The plugin date was not found in /home/i4k/.config/i3situation/plugins
[11/03/2015 12:03:34 AM] - CRITICAL - plugin_manager.py - MainThread - load_objects - Missing plugin date was not found in /home/i4k/.config/i3situation/plugins
[11/03/2015 12:03:34 AM] - ERROR - status.py - MainThread - write - Traceback (most recent call last):

[11/03/2015 12:03:34 AM] - ERROR - status.py - MainThread - write -   File "/usr/bin/i3situation", line 9, in <module>

[11/03/2015 12:03:34 AM] - ERROR - status.py - MainThread - write -     
[11/03/2015 12:03:34 AM] - ERROR - status.py - MainThread - write - load_entry_point('i3situation==1.0.5', 'console_scripts', 'i3situation')()
[11/03/2015 12:03:34 AM] - ERROR - status.py - MainThread - write -   File "/usr/lib/python3.4/site-packages/i3situation/main.py", line 7, in main

[11/03/2015 12:03:34 AM] - ERROR - status.py - MainThread - write -     
[11/03/2015 12:03:34 AM] - ERROR - status.py - MainThread - write - s = status.Status()
[11/03/2015 12:03:34 AM] - ERROR - status.py - MainThread - write -   File "/usr/lib/python3.4/site-packages/i3situation/core/status.py", line 60, in __init__

[11/03/2015 12:03:34 AM] - ERROR - status.py - MainThread - write -     
[11/03/2015 12:03:34 AM] - ERROR - status.py - MainThread - write - self._plugin_path, self.config.plugin)
[11/03/2015 12:03:34 AM] - ERROR - status.py - MainThread - write -   File "/usr/lib/python3.4/site-packages/i3situation/core/plugin_manager.py", line 123, in __init__

[11/03/2015 12:03:34 AM] - ERROR - status.py - MainThread - write -     
[11/03/2015 12:03:34 AM] - ERROR - status.py - MainThread - write - self.objects = self.load_objects()
[11/03/2015 12:03:34 AM] - ERROR - status.py - MainThread - write -   File "/usr/lib/python3.4/site-packages/i3situation/core/plugin_manager.py", line 179, in load_objects

[11/03/2015 12:03:34 AM] - ERROR - status.py - MainThread - write -     
[11/03/2015 12:03:34 AM] - ERROR - status.py - MainThread - write - settings['plugin'], self.dir_path))
[11/03/2015 12:03:34 AM] - ERROR - status.py - MainThread - write - i3situation.core.plugin_manager
[11/03/2015 12:03:34 AM] - ERROR - status.py - MainThread - write - .
[11/03/2015 12:03:34 AM] - ERROR - status.py - MainThread - write - MissingPlugin
[11/03/2015 12:03:34 AM] - ERROR - status.py - MainThread - write - : 
[11/03/2015 12:03:34 AM] - ERROR - status.py - MainThread - write - The plugin date was not found in /home/i4k/.config/i3situation/plugins
[11/03/2015 12:03:43 AM] - CRITICAL - plugin_manager.py - MainThread - load_objects - Missing plugin date_and_time was not found in /home/i4k/.config/i3situation/plugins
[11/03/2015 12:03:43 AM] - ERROR - status.py - MainThread - write - Traceback (most recent call last):

[11/03/2015 12:03:43 AM] - ERROR - status.py - MainThread - write -   File "/usr/bin/i3situation", line 9, in <module>

[11/03/2015 12:03:43 AM] - ERROR - status.py - MainThread - write -     
[11/03/2015 12:03:43 AM] - ERROR - status.py - MainThread - write - load_entry_point('i3situation==1.0.5', 'console_scripts', 'i3situation')()
[11/03/2015 12:03:43 AM] - ERROR - status.py - MainThread - write -   File "/usr/lib/python3.4/site-packages/i3situation/main.py", line 7, in main

[11/03/2015 12:03:43 AM] - ERROR - status.py - MainThread - write -     
[11/03/2015 12:03:43 AM] - ERROR - status.py - MainThread - write - s = status.Status()
[11/03/2015 12:03:43 AM] - ERROR - status.py - MainThread - write -   File "/usr/lib/python3.4/site-packages/i3situation/core/status.py", line 60, in __init__

[11/03/2015 12:03:43 AM] - ERROR - status.py - MainThread - write -     
[11/03/2015 12:03:43 AM] - ERROR - status.py - MainThread - write - self._plugin_path, self.config.plugin)
[11/03/2015 12:03:43 AM] - ERROR - status.py - MainThread - write -   File "/usr/lib/python3.4/site-packages/i3situation/core/plugin_manager.py", line 123, in __init__

[11/03/2015 12:03:43 AM] - ERROR - status.py - MainThread - write -     
[11/03/2015 12:03:43 AM] - ERROR - status.py - MainThread - write - self.objects = self.load_objects()
[11/03/2015 12:03:43 AM] - ERROR - status.py - MainThread - write -   File "/usr/lib/python3.4/site-packages/i3situation/core/plugin_manager.py", line 179, in load_objects

[11/03/2015 12:03:43 AM] - ERROR - status.py - MainThread - write -     
[11/03/2015 12:03:43 AM] - ERROR - status.py - MainThread - write - settings['plugin'], self.dir_path))
[11/03/2015 12:03:43 AM] - ERROR - status.py - MainThread - write - i3situation.core.plugin_manager
[11/03/2015 12:03:43 AM] - ERROR - status.py - MainThread - write - .
[11/03/2015 12:03:43 AM] - ERROR - status.py - MainThread - write - MissingPlugin
[11/03/2015 12:03:43 AM] - ERROR - status.py - MainThread - write - : 
[11/03/2015 12:03:43 AM] - ERROR - status.py - MainThread - write - The plugin date_and_time was not found in /home/i4k/.config/i3situation/plugins
[11/03/2015 03:15:37 AM] - ERROR - status.py - MainThread - write - Traceback (most recent call last):

[11/03/2015 03:15:37 AM] - ERROR - status.py - MainThread - write -   File "/usr/bin/i3situation", line 9, in <module>

[11/03/2015 03:15:37 AM] - ERROR - status.py - MainThread - write -     
[11/03/2015 03:15:37 AM] - ERROR - status.py - MainThread - write - load_entry_point('i3situation==1.0.5', 'console_scripts', 'i3situation')()
[11/03/2015 03:15:37 AM] - ERROR - status.py - MainThread - write -   File "/usr/lib/python3.4/site-packages/i3situation/main.py", line 9, in main

[11/03/2015 03:15:37 AM] - ERROR - status.py - MainThread - write -     
[11/03/2015 03:15:37 AM] - ERROR - status.py - MainThread - write - s.run()
[11/03/2015 03:15:37 AM] - ERROR - status.py - MainThread - write -   File "/usr/lib/python3.4/site-packages/i3situation/core/status.py", line 127, in run

[11/03/2015 03:15:37 AM] - ERROR - status.py - MainThread - write -     
[11/03/2015 03:15:37 AM] - ERROR - status.py - MainThread - write - time.sleep(self.config.general['interval'])
[11/03/2015 03:15:37 AM] - ERROR - status.py - MainThread - write - KeyboardInterrupt
[11/03/2015 03:15:37 AM] - ERROR - status.py - MainThread - write - 
[11/03/2015 03:15:39 AM] - ERROR - status.py - MainThread - write - Exception ignored in: 
[11/03/2015 03:15:39 AM] - ERROR - status.py - MainThread - write - <module 'threading' from '/usr/lib/python3.4/threading.py'>
[11/03/2015 03:15:39 AM] - ERROR - status.py - MainThread - write - Traceback (most recent call last):

[11/03/2015 03:15:39 AM] - ERROR - status.py - MainThread - write -   File "/usr/lib/python3.4/threading.py", line 1294, in _shutdown

[11/03/2015 03:15:39 AM] - ERROR - status.py - MainThread - write -     
[11/03/2015 03:15:39 AM] - ERROR - status.py - MainThread - write - t.join()
[11/03/2015 03:15:39 AM] - ERROR - status.py - MainThread - write -   File "/usr/lib/python3.4/threading.py", line 1060, in join

[11/03/2015 03:15:39 AM] - ERROR - status.py - MainThread - write -     
[11/03/2015 03:15:39 AM] - ERROR - status.py - MainThread - write - self._wait_for_tstate_lock()
[11/03/2015 03:15:39 AM] - ERROR - status.py - MainThread - write -   File "/usr/lib/python3.4/threading.py", line 1076, in _wait_for_tstate_lock

[11/03/2015 03:15:39 AM] - ERROR - status.py - MainThread - write -     
[11/03/2015 03:15:39 AM] - ERROR - status.py - MainThread - write - elif lock.acquire(block, timeout):
[11/03/2015 03:15:39 AM] - ERROR - status.py - MainThread - write - KeyboardInterrupt
[11/03/2015 03:15:45 AM] - ERROR - status.py - MainThread - write - Traceback (most recent call last):

[11/03/2015 03:15:45 AM] - ERROR - status.py - MainThread - write -   File "/usr/bin/i3situation", line 9, in <module>

[11/03/2015 03:15:45 AM] - ERROR - status.py - MainThread - write -     
[11/03/2015 03:15:45 AM] - ERROR - status.py - MainThread - write - load_entry_point('i3situation==1.0.5', 'console_scripts', 'i3situation')()
[11/03/2015 03:15:45 AM] - ERROR - status.py - MainThread - write -   File "/usr/lib/python3.4/site-packages/i3situation/main.py", line 9, in main

[11/03/2015 03:15:45 AM] - ERROR - status.py - MainThread - write -     
[11/03/2015 03:15:45 AM] - ERROR - status.py - MainThread - write - s.run()
[11/03/2015 03:15:45 AM] - ERROR - status.py - MainThread - write -   File "/usr/lib/python3.4/site-packages/i3situation/core/status.py", line 127, in run

[11/03/2015 03:15:45 AM] - ERROR - status.py - MainThread - write -     
[11/03/2015 03:15:45 AM] - ERROR - status.py - MainThread - write - time.sleep(self.config.general['interval'])
[11/03/2015 03:15:45 AM] - ERROR - status.py - MainThread - write - KeyboardInterrupt
[11/03/2015 03:15:45 AM] - ERROR - status.py - MainThread - write - 
[11/03/2015 03:15:46 AM] - ERROR - status.py - MainThread - write - Exception ignored in: 
[11/03/2015 03:15:46 AM] - ERROR - status.py - MainThread - write - <module 'threading' from '/usr/lib/python3.4/threading.py'>
[11/03/2015 03:15:46 AM] - ERROR - status.py - MainThread - write - Traceback (most recent call last):

[11/03/2015 03:15:46 AM] - ERROR - status.py - MainThread - write -   File "/usr/lib/python3.4/threading.py", line 1294, in _shutdown

[11/03/2015 03:15:46 AM] - ERROR - status.py - MainThread - write -     
[11/03/2015 03:15:46 AM] - ERROR - status.py - MainThread - write - t.join()
[11/03/2015 03:15:46 AM] - ERROR - status.py - MainThread - write -   File "/usr/lib/python3.4/threading.py", line 1060, in join

[11/03/2015 03:15:46 AM] - ERROR - status.py - MainThread - write -     
[11/03/2015 03:15:46 AM] - ERROR - status.py - MainThread - write - self._wait_for_tstate_lock()
[11/03/2015 03:15:46 AM] - ERROR - status.py - MainThread - write -   File "/usr/lib/python3.4/threading.py", line 1076, in _wait_for_tstate_lock

[11/03/2015 03:15:46 AM] - ERROR - status.py - MainThread - write -     
[11/03/2015 03:15:46 AM] - ERROR - status.py - MainThread - write - elif lock.acquire(block, timeout):
[11/03/2015 03:15:46 AM] - ERROR - status.py - MainThread - write - KeyboardInterrupt
[11/03/2015 03:24:29 AM] - ERROR - status.py - Thread-9 - write - Exception in thread Thread-9:
Traceback (most recent call last):
  File "/usr/lib/python3.4/threading.py", line 920, in _bootstrap_inner
    self.run()
  File "/usr/lib/python3.4/site-packages/i3situation/core/plugin_manager.py", line 52, in run
    ret = self.func()
  File "usr/lib/python3.4/site-packages/i3situation/plugins/run.py", line 20, in main
  File "/usr/lib/python3.4/subprocess.py", line 620, in check_output
    raise CalledProcessError(retcode, process.args, output=output)
subprocess.CalledProcessError: Command '['sh', '~/.i3/scripts/i3situation/wifi.sh']' returned non-zero exit status 127

[11/03/2015 03:24:39 AM] - ERROR - status.py - Thread-4 - write - Exception in thread Thread-4:
Traceback (most recent call last):
  File "/usr/lib/python3.4/threading.py", line 920, in _bootstrap_inner
    self.run()
  File "/usr/lib/python3.4/site-packages/i3situation/core/plugin_manager.py", line 52, in run
    ret = self.func()
  File "usr/lib/python3.4/site-packages/i3situation/plugins/run.py", line 20, in main
  File "/usr/lib/python3.4/subprocess.py", line 620, in check_output
    raise CalledProcessError(retcode, process.args, output=output)
subprocess.CalledProcessError: Command '['sh', '~/.i3/scripts/i3situation/wifi.sh']' returned non-zero exit status 127

[11/03/2015 03:24:54 AM] - ERROR - status.py - Thread-9 - write - Exception in thread Thread-9:
Traceback (most recent call last):
  File "/usr/lib/python3.4/threading.py", line 920, in _bootstrap_inner
    self.run()
  File "/usr/lib/python3.4/site-packages/i3situation/core/plugin_manager.py", line 52, in run
    ret = self.func()
  File "usr/lib/python3.4/site-packages/i3situation/plugins/run.py", line 20, in main
  File "/usr/lib/python3.4/subprocess.py", line 620, in check_output
    raise CalledProcessError(retcode, process.args, output=output)
subprocess.CalledProcessError: Command '['bash', '~/.i3/scripts/i3situation/wifi.sh']' returned non-zero exit status 127

[11/03/2015 03:25:05 AM] - ERROR - status.py - Thread-14 - write - Exception in thread Thread-14:
Traceback (most recent call last):
  File "/usr/lib/python3.4/threading.py", line 920, in _bootstrap_inner
    self.run()
  File "/usr/lib/python3.4/site-packages/i3situation/core/plugin_manager.py", line 52, in run
    ret = self.func()
  File "usr/lib/python3.4/site-packages/i3situation/plugins/run.py", line 20, in main
  File "/usr/lib/python3.4/subprocess.py", line 607, in check_output
    with Popen(*popenargs, stdout=PIPE, **kwargs) as process:
  File "/usr/lib/python3.4/subprocess.py", line 859, in __init__
    restore_signals, start_new_session)
  File "/usr/lib/python3.4/subprocess.py", line 1457, in _execute_child
    raise child_exception_type(errno_num, err_msg)
FileNotFoundError: [Errno 2] No such file or directory: '"bash'

[11/03/2015 03:25:13 AM] - ERROR - status.py - Thread-19 - write - Exception in thread Thread-19:
Traceback (most recent call last):
  File "/usr/lib/python3.4/threading.py", line 920, in _bootstrap_inner
    self.run()
  File "/usr/lib/python3.4/site-packages/i3situation/core/plugin_manager.py", line 52, in run
    ret = self.func()
  File "usr/lib/python3.4/site-packages/i3situation/plugins/run.py", line 20, in main
  File "/usr/lib/python3.4/subprocess.py", line 620, in check_output
    raise CalledProcessError(retcode, process.args, output=output)
subprocess.CalledProcessError: Command '['bash', '~/.i3/scripts/i3situation/wifi.sh']' returned non-zero exit status 127

[11/03/2015 03:26:03 AM] - ERROR - status.py - Thread-4 - write - Exception in thread Thread-4:
Traceback (most recent call last):
  File "/usr/lib/python3.4/threading.py", line 920, in _bootstrap_inner
    self.run()
  File "/usr/lib/python3.4/site-packages/i3situation/core/plugin_manager.py", line 52, in run
    ret = self.func()
  File "usr/lib/python3.4/site-packages/i3situation/plugins/run.py", line 20, in main
  File "/usr/lib/python3.4/subprocess.py", line 620, in check_output
    raise CalledProcessError(retcode, process.args, output=output)
subprocess.CalledProcessError: Command '['bash', '~/.i3/scripts/i3situation/wifi.sh']' returned non-zero exit status 127

[11/03/2015 03:26:19 AM] - ERROR - status.py - Thread-4 - write - Exception in thread Thread-4:
Traceback (most recent call last):
  File "/usr/lib/python3.4/threading.py", line 920, in _bootstrap_inner
    self.run()
  File "/usr/lib/python3.4/site-packages/i3situation/core/plugin_manager.py", line 52, in run
    ret = self.func()
  File "usr/lib/python3.4/site-packages/i3situation/plugins/run.py", line 20, in main
  File "/usr/lib/python3.4/subprocess.py", line 620, in check_output
    raise CalledProcessError(retcode, process.args, output=output)
subprocess.CalledProcessError: Command '['bash', '~/.i3/scripts/i3situation/wifi.sh']' returned non-zero exit status 127

[11/03/2015 03:26:53 AM] - ERROR - status.py - Thread-4 - write - Exception in thread Thread-4:
Traceback (most recent call last):
  File "/usr/lib/python3.4/threading.py", line 920, in _bootstrap_inner
    self.run()
  File "/usr/lib/python3.4/site-packages/i3situation/core/plugin_manager.py", line 52, in run
    ret = self.func()
  File "usr/lib/python3.4/site-packages/i3situation/plugins/run.py", line 20, in main
  File "/usr/lib/python3.4/subprocess.py", line 620, in check_output
    raise CalledProcessError(retcode, process.args, output=output)
subprocess.CalledProcessError: Command '['bash', '~/.i3/scripts/i3situation/wifi.sh']' returned non-zero exit status 127

[11/03/2015 03:27:29 AM] - ERROR - status.py - Thread-9 - write - Exception in thread Thread-9:
Traceback (most recent call last):
  File "/usr/lib/python3.4/threading.py", line 920, in _bootstrap_inner
    self.run()
  File "/usr/lib/python3.4/site-packages/i3situation/core/plugin_manager.py", line 52, in run
    ret = self.func()
  File "usr/lib/python3.4/site-packages/i3situation/plugins/run.py", line 20, in main
  File "/usr/lib/python3.4/subprocess.py", line 607, in check_output
    with Popen(*popenargs, stdout=PIPE, **kwargs) as process:
  File "/usr/lib/python3.4/subprocess.py", line 859, in __init__
    restore_signals, start_new_session)
  File "/usr/lib/python3.4/subprocess.py", line 1457, in _execute_child
    raise child_exception_type(errno_num, err_msg)
PermissionError: [Errno 13] Permission denied

[11/03/2015 03:27:32 AM] - ERROR - status.py - Thread-4 - write - Exception in thread Thread-4:
Traceback (most recent call last):
  File "/usr/lib/python3.4/threading.py", line 920, in _bootstrap_inner
    self.run()
  File "/usr/lib/python3.4/site-packages/i3situation/core/plugin_manager.py", line 52, in run
    ret = self.func()
  File "usr/lib/python3.4/site-packages/i3situation/plugins/run.py", line 20, in main
  File "/usr/lib/python3.4/subprocess.py", line 607, in check_output
    with Popen(*popenargs, stdout=PIPE, **kwargs) as process:
  File "/usr/lib/python3.4/subprocess.py", line 859, in __init__
    restore_signals, start_new_session)
  File "/usr/lib/python3.4/subprocess.py", line 1457, in _execute_child
    raise child_exception_type(errno_num, err_msg)
PermissionError: [Errno 13] Permission denied

[11/03/2015 03:41:10 AM] - ERROR - status.py - Thread-24 - write - Exception in thread Thread-24:
Traceback (most recent call last):
  File "/usr/lib/python3.4/threading.py", line 920, in _bootstrap_inner
    self.run()
  File "/usr/lib/python3.4/site-packages/i3situation/core/plugin_manager.py", line 52, in run
    ret = self.func()
  File "usr/lib/python3.4/site-packages/i3situation/plugins/run.py", line 20, in main
  File "/usr/lib/python3.4/subprocess.py", line 620, in check_output
    raise CalledProcessError(retcode, process.args, output=output)
subprocess.CalledProcessError: Command '['sh', '/home/i4k/.i3/scripts/i3situation/wifi.sh']' returned non-zero exit status 2

[11/03/2015 03:41:44 AM] - ERROR - status.py - Thread-4 - write - Exception in thread Thread-4:
Traceback (most recent call last):
  File "/usr/lib/python3.4/threading.py", line 920, in _bootstrap_inner
    self.run()
  File "/usr/lib/python3.4/site-packages/i3situation/core/plugin_manager.py", line 52, in run
    ret = self.func()
  File "usr/lib/python3.4/site-packages/i3situation/plugins/run.py", line 20, in main
  File "/usr/lib/python3.4/subprocess.py", line 620, in check_output
    raise CalledProcessError(retcode, process.args, output=output)
subprocess.CalledProcessError: Command '['sh', '/home/i4k/.i3/scripts/i3situation/wifi.sh']' returned non-zero exit status 2

[11/03/2015 03:43:17 AM] - ERROR - status.py - Thread-4 - write - Exception in thread Thread-4:
Traceback (most recent call last):
  File "/usr/lib/python3.4/threading.py", line 920, in _bootstrap_inner
    self.run()
  File "/usr/lib/python3.4/site-packages/i3situation/core/plugin_manager.py", line 52, in run
    ret = self.func()
  File "usr/lib/python3.4/site-packages/i3situation/plugins/run.py", line 20, in main
  File "/usr/lib/python3.4/subprocess.py", line 620, in check_output
    raise CalledProcessError(retcode, process.args, output=output)
subprocess.CalledProcessError: Command '['sh', '/home/i4k/.i3/scripts/i3situation/wifi.sh']' returned non-zero exit status 2

[11/03/2015 03:50:48 AM] - ERROR - status.py - Thread-4 - write - Exception in thread Thread-4:
Traceback (most recent call last):
  File "/usr/lib/python3.4/threading.py", line 920, in _bootstrap_inner
    self.run()
  File "/usr/lib/python3.4/site-packages/i3situation/core/plugin_manager.py", line 52, in run
    ret = self.func()
  File "usr/lib/python3.4/site-packages/i3situation/plugins/run.py", line 20, in main
  File "/usr/lib/python3.4/subprocess.py", line 620, in check_output
    raise CalledProcessError(retcode, process.args, output=output)
subprocess.CalledProcessError: Command '['sh', '/home/i4k/.i3/scripts/i3situation/wifi.sh']' returned non-zero exit status 127

[11/03/2015 02:51:59 PM] - ERROR - status.py - Thread-3 - write - Exception in thread Thread-3:
Traceback (most recent call last):
  File "/usr/lib/python3.4/site-packages/requests/packages/urllib3/connectionpool.py", line 544, in urlopen
    body=body, headers=headers)
  File "/usr/lib/python3.4/site-packages/requests/packages/urllib3/connectionpool.py", line 349, in _make_request
    conn.request(method, url, **httplib_request_kw)
  File "/usr/lib/python3.4/http/client.py", line 1088, in request
    self._send_request(method, url, body, headers)
  File "/usr/lib/python3.4/http/client.py", line 1126, in _send_request
    self.endheaders(body)
  File "/usr/lib/python3.4/http/client.py", line 1084, in endheaders
    self._send_output(message_body)
  File "/usr/lib/python3.4/http/client.py", line 922, in _send_output
    self.send(msg)
  File "/usr/lib/python3.4/http/client.py", line 857, in send
    self.connect()
  File "/usr/lib/python3.4/site-packages/requests/packages/urllib3/connection.py", line 155, in connect
    conn = self._new_conn()
  File "/usr/lib/python3.4/site-packages/requests/packages/urllib3/connection.py", line 134, in _new_conn
    (self.host, self.port), self.timeout, **extra_kw)
  File "/usr/lib/python3.4/site-packages/requests/packages/urllib3/util/connection.py", line 64, in create_connection
    for res in socket.getaddrinfo(host, port, 0, socket.SOCK_STREAM):
  File "/usr/lib/python3.4/socket.py", line 533, in getaddrinfo
    for res in _socket.getaddrinfo(host, port, family, type, proto, flags):
socket.gaierror: [Errno -2] Name or service not known

During handling of the above exception, another exception occurred:

Traceback (most recent call last):
  File "/usr/lib/python3.4/site-packages/requests/adapters.py", line 370, in send
    timeout=timeout
  File "/usr/lib/python3.4/site-packages/requests/packages/urllib3/connectionpool.py", line 597, in urlopen
    _stacktrace=sys.exc_info()[2])
  File "/usr/lib/python3.4/site-packages/requests/packages/urllib3/util/retry.py", line 245, in increment
    raise six.reraise(type(error), error, _stacktrace)
  File "/usr/lib/python3.4/site-packages/requests/packages/urllib3/packages/six.py", line 309, in reraise
    raise value.with_traceback(tb)
  File "/usr/lib/python3.4/site-packages/requests/packages/urllib3/connectionpool.py", line 544, in urlopen
    body=body, headers=headers)
  File "/usr/lib/python3.4/site-packages/requests/packages/urllib3/connectionpool.py", line 349, in _make_request
    conn.request(method, url, **httplib_request_kw)
  File "/usr/lib/python3.4/http/client.py", line 1088, in request
    self._send_request(method, url, body, headers)
  File "/usr/lib/python3.4/http/client.py", line 1126, in _send_request
    self.endheaders(body)
  File "/usr/lib/python3.4/http/client.py", line 1084, in endheaders
    self._send_output(message_body)
  File "/usr/lib/python3.4/http/client.py", line 922, in _send_output
    self.send(msg)
  File "/usr/lib/python3.4/http/client.py", line 857, in send
    self.connect()
  File "/usr/lib/python3.4/site-packages/requests/packages/urllib3/connection.py", line 155, in connect
    conn = self._new_conn()
  File "/usr/lib/python3.4/site-packages/requests/packages/urllib3/connection.py", line 134, in _new_conn
    (self.host, self.port), self.timeout, **extra_kw)
  File "/usr/lib/python3.4/site-packages/requests/packages/urllib3/util/connection.py", line 64, in create_connection
    for res in socket.getaddrinfo(host, port, 0, socket.SOCK_STREAM):
  File "/usr/lib/python3.4/socket.py", line 533, in getaddrinfo
    for res in _socket.getaddrinfo(host, port, family, type, proto, flags):
requests.packages.urllib3.exceptions.ProtocolError: ('Connection aborted.', gaierror(-2, 'Name or service not known'))

During handling of the above exception, another exception occurred:

Traceback (most recent call last):
  File "/usr/lib/python3.4/threading.py", line 920, in _bootstrap_inner
    self.run()
  File "/usr/lib/python3.4/site-packages/i3situation/core/plugin_manager.py", line 52, in run
    ret = self.func()
  File "usr/lib/python3.4/site-packages/i3situation/plugins/reddit.py", line 71, in main
  File "usr/lib/python3.4/site-packages/i3situation/plugins/reddit.py", line 112, in manage_submissions
  File "usr/lib/python3.4/site-packages/i3situation/plugins/reddit.py", line 123, in get_submissions
  File "/usr/lib/python3.4/site-packages/requests/sessions.py", line 473, in get
    return self.request('GET', url, **kwargs)
  File "/usr/lib/python3.4/site-packages/requests/sessions.py", line 461, in request
    resp = self.send(prep, **send_kwargs)
  File "/usr/lib/python3.4/site-packages/requests/sessions.py", line 573, in send
    r = adapter.send(request, **kwargs)
  File "/usr/lib/python3.4/site-packages/requests/adapters.py", line 415, in send
    raise ConnectionError(err, request=request)
requests.exceptions.ConnectionError: ('Connection aborted.', gaierror(-2, 'Name or service not known'))

